<?xml version="1.0"?>
<robot name="assignment_bot">

####################### BASE LINK #######################
	<link name="base_link">
		<visual>
			<geometry>
        			<mesh filename="package://mcubot/meshes/base.stl" scale="1 1 1"/>
      			</geometry>
			<material name="green">
        		<color rgba="0 1 0 1"/>
    			</material>
		</visual>
		<collision>
			<origin xyz="0 0 0" rpy="0 0 0"/>
			<geometry>
				<box size="0.6 0.3 0.08"/>
			</geometry>
		</collision>
		<inertial>
			<mass value="1.0"/>
			<inertia ixx="0.001" iyy="0.001" izz="0.001"
			ixy="0" ixz="0" iyz="0"/>
		</inertial>
	</link>
####################### CAMERA LINK #######################
	<link name="camera">
		<visual>
			<geometry>
				<cylinder radius="0.03" length="0.1"/>
			</geometry>
			<material name="green"/>
		</visual>
		<collision>
			<origin xyz="0 0 0" rpy="0 0 0"/>
			<geometry>
				<cylinder radius="0.03" length="0.1"/>
			</geometry>
		</collision>
		<inertial>
			<mass value="1.0"/>
			<inertia ixx="0.001" iyy="0.001" izz="0.001"
			ixy="0" ixz="0" iyz="0"/>
		</inertial>
	</link>
	<joint name="camera_joint" type="fixed">
		<axis xyz="0 0 1"/>
		<parent link="base_link"/>
		<child link="camera"/>
		<origin rpy="0 0 0" xyz="0.32 0 0.04"/>
	</joint>
####################### TORSO LINKS #######################
	<link name="torso_base_box">
		<visual>
			<geometry>
				<box size="0.25 0.25 0.08"/>
			</geometry>
			<material name="red">
   				<color rgba="1 0 0 1"/>
  			</material>
		</visual>
		<collision>
			<origin xyz="0 0 0" rpy="0 0 0"/>
			<geometry>
				<box size="0.25 0.25 0.08"/>
			</geometry>
		</collision>
		<inertial>
			<mass value="1.0"/>
			<inertia ixx="0.001" iyy="0.001" izz="0.001"
			ixy="0" ixz="0" iyz="0"/>
		</inertial>
	</link>
	<joint name="torso_base_box_joint" type="fixed">
		<axis xyz="0 0 1"/>
		<parent link="base_link"/>
		<child link="torso_base_box"/>
		<origin rpy="0 0 0" xyz="0.05 0 0.08"/>
	</joint>

	<link name="torso_base_cylinder">
		<visual>
			<geometry>
				<cylinder radius="0.125" length="0.10"/>
			</geometry>
			<material name="red"/>
		</visual>
		<collision>
			<origin xyz="0 0 0" rpy="0 0 0"/>
			<geometry>
				<cylinder radius="0.125" length="0.10"/>
			</geometry>
		</collision>
		<inertial>
			<mass value="1.0"/>
			<inertia ixx="0.001" iyy="0.001" izz="0.001"
			ixy="0" ixz="0" iyz="0"/>
		</inertial>
	</link>
	<joint name="torso_base_cylinder_joint" type="fixed">
		<axis xyz="0 0 1"/>
		<parent link="base_link"/>
		<child link="torso_base_cylinder"/>
		<origin rpy="0 0 0" xyz="0.05 0 0.17"/>
	</joint>

	<link name="torso">
		<visual>
			<geometry>
				<cylinder radius="0.0575" length="0.3"/>
			</geometry>
			<material name="red"/>
		</visual>
		<collision>
			<origin xyz="0 0 0" rpy="0 0 0"/>
			<geometry>
				<cylinder radius="0.0575" length="0.3"/>
			</geometry>
		</collision>
		<inertial>
			<mass value="1.0"/>
			<inertia ixx="0.001" iyy="0.001" izz="0.001"
			ixy="0" ixz="0" iyz="0"/>
		</inertial>
	</link>
	<joint name="torso_joint" type="revolute">
		<axis xyz="0 0 1"/>
		<parent link="torso_base_cylinder"/>
		<child link="torso"/>
		<limit effort="30" velocity="1.0" lower="-2" upper="2" />
		<origin rpy="0 0 0" xyz="0 0 0.2"/>
	</joint>
####################### HEAD LINKS #######################
	<link name="head_pan_base">
		<visual>
			<geometry>
				<box size="0.06 0.06 0.02"/>
			</geometry>
			<material name="red"/>
		</visual>
		<collision>
			<origin xyz="0 0 0" rpy="0 0 0"/>
			<geometry>
				<box size="0.06 0.06 0.02"/>
			</geometry>
		</collision>
		<inertial>
			<mass value="1.0"/>
			<inertia ixx="0.001" iyy="0.001" izz="0.001"
			ixy="0" ixz="0" iyz="0"/>
		</inertial>
	</link>
	<joint name="head_pan_base_joint" type="fixed">
		<axis xyz="0 0 1"/>
		<parent link="torso"/>
		<child link="head_pan_base"/>
		<origin rpy="0 0 0" xyz="0 0 0.16"/>
	</joint>

	<link name="head_pan">
		<visual>
			<geometry>
				<box size="0.03 0.05 0.02"/>
			</geometry>
			<material name="green">
        		<color rgba="0 1 0 1"/>
    		</material>
		</visual>
		<collision>
			<origin xyz="0 0 0" rpy="0 0 0"/>
			<geometry>
				<box size="0.03 0.05 0.02"/>
			</geometry>
		</collision>
		<inertial>
			<mass value="1.0"/>
			<inertia ixx="0.001" iyy="0.001" izz="0.001"
			ixy="0" ixz="0" iyz="0"/>
		</inertial>
	</link>
	<joint name="head_pan_joint" type="continuous">
		<axis xyz="0 0 1"/>
		<parent link="head_pan_base"/>
		<child link="head_pan"/>
		<origin rpy="0 0 0" xyz="0 0 0.02"/>
	</joint>

	<link name="head_tilt">		
		<visual>
			<geometry>
				<box size="0.03 0.05 0.04"/>
			</geometry>
			<material name="green">
        		<color rgba="0 1 0 1"/>
    		</material>
		</visual>
		<collision>
			<origin xyz="0 0 0" rpy="0 0 0"/>
			<geometry>
				<box size="0.03 0.05 0.04"/>
			</geometry>
		</collision>
		<inertial>
			<mass value="1.0"/>
			<inertia ixx="0.001" iyy="0.001" izz="0.001"
			ixy="0" ixz="0" iyz="0"/>
		</inertial>
	</link>
	<joint name="head_tilt_joint" type="revolute">
		<axis xyz="0 1 0"/>
		<parent link="head_pan"/>
		<child link="head_tilt"/>
		<limit effort="30" velocity="1.0" lower="-1" upper="0.4" />
		<origin rpy="0 0 0" xyz="0 0 0.03"/>
	</joint>

	<link name="head_antenna">		
		<visual>
			<geometry>
				<box size="0.03 0.08 0.12"/>
			</geometry>
			<material name="grey">
        		<color rgba=".2 .2 .2 1"/>
    		</material>
		</visual>
		<collision>
			<origin xyz="0 0 0" rpy="0 0 0"/>
			<geometry>
				<box size="0.03 0.08 0.12"/>
			</geometry>
		</collision>
		<inertial>
			<mass value="1.0"/>
			<inertia ixx="0.001" iyy="0.001" izz="0.001"
			ixy="0" ixz="0" iyz="0"/>
		</inertial>
	</link>
	<joint name="head_antenna_joint" type="fixed">
		<axis xyz="0 1 0"/>
		<parent link="head_tilt"/>
		<child link="head_antenna"/>
		<origin rpy="0 0 0" xyz="0.05 0 0.04"/>
	</joint>

	<link name="hac">		#hac = head antenna cylinder
		<visual>
			<geometry>
				<cylinder radius="0.004" length="0.08"/>
			</geometry>
			<material name="grey"/>
		</visual>
		<collision>
			<origin xyz="0 0 0" rpy="0 0 0"/>
			<geometry>
				<cylinder radius="0.004" length="0.08"/>
			</geometry>
		</collision>
		<inertial>
			<mass value="1.0"/>
			<inertia ixx="0.001" iyy="0.001" izz="0.001"
			ixy="0" ixz="0" iyz="0"/>
		</inertial>
	</link>
	<joint name="hac_joint" type="fixed">
		<axis xyz="0 0 1"/>
		<parent link="head_antenna"/>
		<child link="hac"/>
		<origin rpy="0 0 0" xyz="0 -0.03 0.1"/>
	</joint>
####################### SHOULDER LINKS #######################
	<link name="shoulder_box1">		
		<visual>
			<geometry>
				<box size="0.03 0.02 0.04"/>
			</geometry>
			<material name="green"/>
		</visual>
		<collision>
			<origin xyz="0 0 0" rpy="0 0 0"/>
			<geometry>
				<box size="0.03 0.02 0.04"/>
			</geometry>
		</collision>
		<inertial>
			<mass value="1.0"/>
			<inertia ixx="0.001" iyy="0.001" izz="0.001"
			ixy="0" ixz="0" iyz="0"/>
		</inertial>
	</link>
	<joint name="shoulder_box1_joint" type="fixed">
		<axis xyz="0 0 0"/>
		<parent link="torso"/>
		<child link="shoulder_box1"/>
		<origin rpy="0 0 0" xyz="0 0.065 0.07"/>
	</joint>

	<link name="shoulder_box2">		
		<visual>
			<geometry>
				<box size="0.03 0.02 0.04"/>
			</geometry>
			<material name="green"/>
		</visual>
		<collision>
			<origin xyz="0 0 0" rpy="0 0 0"/>
			<geometry>
				<box size="0.03 0.02 0.04"/>
			</geometry>
		</collision>
		<inertial>
			<mass value="1.0"/>
			<inertia ixx="0.001" iyy="0.001" izz="0.001"
			ixy="0" ixz="0" iyz="0"/>
		</inertial>
	</link>
	<joint name="shoulder_box2_joint" type="fixed">
		<axis xyz="0 0 0"/>
		<parent link="torso"/>
		<child link="shoulder_box2"/>
		<origin rpy="0 0 0" xyz="0 -0.065 0.07"/>
	</joint>

	<link name="left_shoulder_forward">		
		<visual>
			<geometry>
				<box size="0.035 0.04 0.05"/>
			</geometry>
			<material name="blue">
        		<color rgba="0 0 1 1"/>
    		</material>
		</visual>
		<collision>
			<origin xyz="0 0 0" rpy="0 0 0"/>
			<geometry>
				<box size="0.035 0.04 0.05"/>
			</geometry>
		</collision>
		<inertial>
			<mass value="1.0"/>
			<inertia ixx="0.001" iyy="0.001" izz="0.001"
			ixy="0" ixz="0" iyz="0"/>
		</inertial>
	</link>
	<joint name="left_shoulder_forward_joint" type="revolute">
		<axis xyz="0 0 1"/>
		<parent link="shoulder_box1"/>
		<child link="left_shoulder_forward"/>
		<limit effort="30" velocity="1.0" lower="-0.29" upper="0.8" />
		<origin rpy="0 0 0" xyz="0 0.03 0"/>
	</joint>

	<link name="right_shoulder_forward">		
		<visual>
			<geometry>
				<box size="0.035 0.04 0.05"/>
			</geometry>
			<material name="blue">
        		<color rgba="0 0 1 1"/>
    		</material>
		</visual>
		<collision>
			<origin xyz="0 0 0" rpy="0 0 0"/>
			<geometry>
				<box size="0.035 0.04 0.05"/>
			</geometry>
		</collision>
		<inertial>
			<mass value="1.0"/>
			<inertia ixx="0.001" iyy="0.001" izz="0.001"
			ixy="0" ixz="0" iyz="0"/>
		</inertial>
	</link>
	<joint name="right_shoulder_forward_joint" type="revolute">
		<axis xyz="0 0 1"/>
		<parent link="shoulder_box2"/>
		<child link="right_shoulder_forward"/>
		<limit effort="30" velocity="1.0" lower="-0.8" upper="0.29" />
		<origin rpy="0 0 0" xyz="0 -0.03 0"/>
	</joint>

	<link name="left_shoulder_up">		
		<visual>
			<geometry>
				<box size="0.07 0.03 0.05"/>
			</geometry>
			<material name="blue">
        		<color rgba="0 0 1 1"/>
    		</material>
		</visual>
		<collision>
			<origin xyz="0 0 0" rpy="0 0 0"/>
			<geometry>
				<box size="0.07 0.03 0.05"/>
			</geometry>
		</collision>
		<inertial>
			<mass value="1.0"/>
			<inertia ixx="0.001" iyy="0.001" izz="0.001"
			ixy="0" ixz="0" iyz="0"/>
		</inertial>
	</link>
	<joint name="left_shoulder_up_joint" type="revolute">
		<axis xyz="0 1 0"/>
		<parent link="left_shoulder_forward"/>
		<child link="left_shoulder_up"/>
		<limit effort="30" velocity="1.0" lower="-1" upper="1" />
		<origin rpy="0 0 0" xyz="0.02 0.035 0"/>
	</joint>

	<link name="right_shoulder_up">		
		<visual>
			<geometry>
				<box size="0.07 0.03 0.05"/>
			</geometry>
			<material name="blue"/>
		</visual>
		<collision>
			<origin xyz="0 0 0" rpy="0 0 0"/>
			<geometry>
				<box size="0.07 0.03 0.05"/>
			</geometry>
		</collision>
		<inertial>
			<mass value="1.0"/>
			<inertia ixx="0.001" iyy="0.001" izz="0.001"
			ixy="0" ixz="0" iyz="0"/>
		</inertial>
	</link>
	<joint name="right_shoulder_up_joint" type="revolute">
		<axis xyz="0 1 0"/>
		<parent link="right_shoulder_forward"/>
		<child link="right_shoulder_up"/>
		<limit effort="30" velocity="1.0" lower="-1" upper="1" />
		<origin rpy="0 0 0" xyz="0.02 -0.035 0"/>
	</joint>
####################### ARM LINKS #######################
	<link name="left_upper_limb">
		<visual>
			<geometry>
				<cylinder radius="0.008" length="0.08"/>
			</geometry>
			<material name="grey"/>
		</visual>
		<collision>
			<origin xyz="0 0 0" rpy="0 0 0"/>
			<geometry>
				<cylinder radius="0.008" length="0.08"/>
			</geometry>
		</collision>
		<inertial>
			<mass value="1.0"/>
			<inertia ixx="0.001" iyy="0.001" izz="0.001"
			ixy="0" ixz="0" iyz="0"/>
		</inertial>
	</link>
	<joint name="left_upper_limb_joint" type="fixed">
		<axis xyz="0 0 0"/>
		<parent link="left_shoulder_up"/>
		<child link="left_upper_limb"/>
		<origin rpy="0 1.57 0" xyz="0.075 0 0"/>
	</joint>

	<link name="right_upper_limb">
		<visual>
			<geometry>
				<cylinder radius="0.008" length="0.08"/>
			</geometry>
			<material name="grey"/>
		</visual>
		<collision>
			<origin xyz="0 0 0" rpy="0 0 0"/>
			<geometry>
				<cylinder radius="0.008" length="0.08"/>
			</geometry>
		</collision>
		<inertial>
			<mass value="1.0"/>
			<inertia ixx="0.001" iyy="0.001" izz="0.001"
			ixy="0" ixz="0" iyz="0"/>
		</inertial>
	</link>
	<joint name="right_upper_limb_joint" type="fixed">
		<axis xyz="0 0 0"/>
		<parent link="right_shoulder_up"/>
		<child link="right_upper_limb"/>
		<origin rpy="0 1.57 0" xyz="0.075 0 0"/>
	</joint>

	<link name="left_elbow">		
		<visual>
			<geometry>
				<box size="0.07 0.03 0.05"/>
			</geometry>
			<material name="blue"/>
		</visual>
		<collision>
			<origin xyz="0 0 0" rpy="0 0 0"/>
			<geometry>
				<box size="0.07 0.03 0.05"/>
			</geometry>
		</collision>
		<inertial>
			<mass value="1.0"/>
			<inertia ixx="0.001" iyy="0.001" izz="0.001"
			ixy="0" ixz="0" iyz="0"/>
		</inertial>
	</link>
	<joint name="left_elbow_joint" type="revolute">
		<axis xyz="1 0 0"/>
		<parent link="left_upper_limb"/>
		<child link="left_elbow"/>
		<limit effort="30" velocity="1.0" lower="-1.57" upper="1.57" />
		<origin rpy="0 1.57 0" xyz="0 0 0.075"/>
	</joint>

	<link name="right_elbow">		
		<visual>
			<geometry>
				<box size="0.07 0.03 0.05"/>
			</geometry>
			<material name="blue"/>
		</visual>
		<collision>
			<origin xyz="0 0 0" rpy="0 0 0"/>
			<geometry>
				<box size="0.07 0.03 0.05"/>
			</geometry>
		</collision>
		<inertial>
			<mass value="1.0"/>
			<inertia ixx="0.001" iyy="0.001" izz="0.001"
			ixy="0" ixz="0" iyz="0"/>
		</inertial>
	</link>
	<joint name="right_elbow_joint" type="revolute">
		<axis xyz="1 0 0"/>
		<parent link="right_upper_limb"/>
		<child link="right_elbow"/>
		<limit effort="30" velocity="1.0" lower="-1.57" upper="1.57" />
		<origin rpy="0 1.57 0" xyz="0 0 0.075"/>
	</joint>

	<link name="left_forearm">
		<visual>
			<geometry>
				<cylinder radius="0.008" length="0.08"/>
			</geometry>
			<material name="grey"/>
		</visual>
		<collision>
			<origin xyz="0 0 0" rpy="0 0 0"/>
			<geometry>
				<cylinder radius="0.008" length="0.08"/>
			</geometry>
		</collision>
		<inertial>
			<mass value="1.0"/>
			<inertia ixx="0.001" iyy="0.001" izz="0.001"
			ixy="0" ixz="0" iyz="0"/>
		</inertial>
	</link>
	<joint name="left_forearm_joint" type="fixed">
		<axis xyz="0 0 0"/>
		<parent link="left_elbow"/>
		<child link="left_forearm"/>
		<origin rpy="0 1.57 0" xyz="-0.075 0 0"/>
	</joint>

	<link name="right_forearm">
		<visual>
			<geometry>
				<cylinder radius="0.008" length="0.08"/>
			</geometry>
			<material name="grey"/>
		</visual>
		<collision>
			<origin xyz="0 0 0" rpy="0 0 0"/>
			<geometry>
				<cylinder radius="0.008" length="0.08"/>
			</geometry>
		</collision>
		<inertial>
			<mass value="1.0"/>
			<inertia ixx="0.001" iyy="0.001" izz="0.001"
			ixy="0" ixz="0" iyz="0"/>
		</inertial>
	</link>
	<joint name="right_forearm_joint" type="fixed">
		<axis xyz="0 0 0"/>
		<parent link="right_elbow"/>
		<child link="right_forearm"/>
		<origin rpy="0 1.57 0" xyz="-0.075 0 0"/>
	</joint>
####################### HAND LINKS #######################
	<link name="left_wrist">		
		<visual>
			<geometry>
				<box size="0.07 0.03 0.05"/>
			</geometry>
			<material name="blue"/>
		</visual>
		<collision>
			<origin xyz="0 0 0" rpy="0 0 0"/>
			<geometry>
				<box size="0.07 0.03 0.05"/>
			</geometry>
		</collision>
		<inertial>
			<mass value="1.0"/>
			<inertia ixx="0.001" iyy="0.001" izz="0.001"
			ixy="0" ixz="0" iyz="0"/>
		</inertial>
	</link>
	<joint name="left_wrist_joint" type="revolute">
		<axis xyz="0 0 1"/>
		<parent link="left_forearm"/>
		<child link="left_wrist"/>
		<limit effort="30" velocity="1.0" lower="-1.57" upper="1.57" />
		<origin rpy="0 1.57 0" xyz="0 0 -0.075"/>
	</joint>

	<link name="right_wrist">		
		<visual>
			<geometry>
				<box size="0.07 0.03 0.05"/>
			</geometry>
			<material name="blue"/>
		</visual>
		<collision>
			<origin xyz="0 0 0" rpy="0 0 0"/>
			<geometry>
				<box size="0.07 0.03 0.05"/>
			</geometry>
		</collision>
		<inertial>
			<mass value="1.0"/>
			<inertia ixx="0.001" iyy="0.001" izz="0.001"
			ixy="0" ixz="0" iyz="0"/>
		</inertial>
	</link>
	<joint name="right_wrist_joint" type="revolute">
		<axis xyz="0 0 1"/>
		<parent link="right_forearm"/>
		<child link="right_wrist"/>
		<limit effort="30" velocity="1.0" lower="-1.57" upper="1.57" />
		<origin rpy="0 1.57 0" xyz="0 0 -0.075"/>
	</joint>

	<link name="left_hand">		
		<visual>
			<geometry>
				<box size="0.07 0.01 0.05"/>
			</geometry>
			<material name="grey"/>
		</visual>
		<collision>
			<origin xyz="0 0 0" rpy="0 0 0"/>
			<geometry>
				<box size="0.07 0.01 0.05"/>
			</geometry>
		</collision>
		<inertial>
			<mass value="1.0"/>
			<inertia ixx="0.001" iyy="0.001" izz="0.001"
			ixy="0" ixz="0" iyz="0"/>
		</inertial>
	</link>
	<joint name="left_hand_joint" type="fixed">
		<axis xyz="0 0 0"/>
		<parent link="left_wrist"/>
		<child link="left_hand"/>
		<origin rpy="0 0 0" xyz="0.07 0 0"/>
	</joint>

	<link name="right_hand">		
		<visual>
			<geometry>
				<box size="0.07 0.01 0.05"/>
			</geometry>
			<material name="grey"/>
		</visual>
		<collision>
			<origin xyz="0 0 0" rpy="0 0 0"/>
			<geometry>
				<box size="0.07 0.01 0.05"/>
			</geometry>
		</collision>
		<inertial>
			<mass value="1.0"/>
			<inertia ixx="0.001" iyy="0.001" izz="0.001"
			ixy="0" ixz="0" iyz="0"/>
		</inertial>
	</link>
	<joint name="right_hand_joint" type="fixed">
		<axis xyz="0 0 0"/>
		<parent link="right_wrist"/>
		<child link="right_hand"/>
		<origin rpy="0 0 0" xyz="0.07 0 0"/>
	</joint>
####################### WHEEL LINKS #######################
	<link name="left_wheel">
		<visual>
			<geometry>
				<cylinder radius="0.04" length="0.02"/>
			</geometry>
			<material name="red"/>
		</visual>
		<collision>
			<origin xyz="0 0 0" rpy="0 0 0"/>
			<geometry>
				<cylinder radius="0.04" length="0.02"/>
			</geometry>
		</collision>
		<inertial>
			<mass value="1.0"/>
			<inertia ixx="0.001" iyy="0.001" izz="0.001"
			ixy="0" ixz="0" iyz="0"/>
		</inertial>
	</link>
	<joint name="left_wheel_joint" type="continuous">
		<axis xyz="0 0 1"/>
		<parent link="base_link"/>
		<child link="left_wheel"/>
		<origin rpy="1.57 0 0" xyz="0 0.16 -0.025"/>
	</joint>

	<link name="right_wheel">
		<visual>
			<geometry>
				<cylinder radius="0.04" length="0.02"/>
			</geometry>
			<material name="red"/>
		</visual>
		<collision>
			<origin xyz="0 0 0" rpy="0 0 0"/>
			<geometry>
				<cylinder radius="0.04" length="0.02"/>
			</geometry>
		</collision>
		<inertial>
			<mass value="1.0"/>
			<inertia ixx="0.001" iyy="0.001" izz="0.001"
			ixy="0" ixz="0" iyz="0"/>
		</inertial>
	</link>
	<joint name="right_wheel_joint" type="continuous">
		<axis xyz="0 0 1"/>
		<parent link="base_link"/>
		<child link="right_wheel"/>
		<origin rpy="1.57 0 0" xyz="0 -0.16 -0.025"/>
	</joint>
####################### CASTER LINKS #######################
	<link name="front_caster">
		<visual>
			<geometry>
				<sphere radius="0.04"/>
			</geometry>
			<material name="red"/>
		</visual>
		<collision>
			<origin xyz="0 0 0" rpy="0 0 0"/>
			<geometry>
				<sphere radius="0.04"/>
			</geometry>
		</collision>
		<inertial>
			<mass value="1.0"/>
			<inertia ixx="0.001" iyy="0.001" izz="0.001"
			ixy="0" ixz="0" iyz="0"/>
		</inertial>
	</link>
	<joint name="front_caster_joint" type="continuous">
		<axis xyz="1 1 1"/>
		<parent link="base_link"/>
		<child link="front_caster"/>
		<origin rpy="0 0 0" xyz="0.25 0 -0.030"/>
	</joint>

	<link name="rear_caster">
		<visual>
			<geometry>
				<sphere radius="0.04"/>
			</geometry>
			<material name="red"/>
		</visual>
		<collision>
			<origin xyz="0 0 0" rpy="0 0 0"/>
			<geometry>
				<sphere radius="0.04"/>
			</geometry>
		</collision>
		<inertial>
			<mass value="1.0"/>
			<inertia ixx="0.001" iyy="0.001" izz="0.001"
			ixy="0" ixz="0" iyz="0"/>
		</inertial>
	</link>
	<joint name="rear_caster_joint" type="continuous">
		<axis xyz="1 1 1"/>
		<parent link="base_link"/>
		<child link="rear_caster"/>
		<origin rpy="0 0 0" xyz="-0.25 0 -0.030"/>
	</joint>

####################### GAZEBO PLUGINS #######################

<gazebo>
	<plugin name="joint_state_publisher" filename="libgazebo_ros_joint_state_publisher.so">
		<jointName>front_caster_joint, rear_caster_joint</jointName>
	</plugin>
</gazebo>



####################### DIFFERENTIAL DRIVE PLUGIN #######################
	<gazebo>
		<plugin name="differential_drive_controller" filename="libgazebo_ros_diff_drive.so">
			<commandTopic>cmd_vel</commandTopic>
			<odometryTopic>odom</odometryTopic>
			<odometryFrame>odom</odometryFrame>
			<odometrySource>world</odometrySource>
			<publishOdomTF>true</publishOdomTF>
			<robotBaseFrame>base_link</robotBaseFrame>	<!-- base_frame link -->
			<publishWheelTF>false</publishWheelTF>
			<publishTf>true</publishTf>
			<publishWheelJointState>true</publishWheelJointState>
			<legacyMode>false</legacyMode>
			<updateRate>30</updateRate>
			<leftJoint>left_wheel_joint</leftJoint>		<!-- left wheel joint name -->
			<rightJoint>right_wheel_joint</rightJoint>	<!-- right wheel joint name -->
			<wheelSeparation>0.32</wheelSeparation>		<!-- distance between wheel -->
			<wheelDiameter>0.06</wheelDiameter>		<!-- wheel diameter -->
			<wheelAcceleration>1</wheelAcceleration>
			<wheelTorque>10</wheelTorque>
			<rosDebugLevel>na</rosDebugLevel>
		</plugin>
	</gazebo>
####################### CAMERA SENSOR PLUGIN #######################
	<gazebo reference="camera">
	    <material>Gazebo/Green</material>
	    <sensor type="camera" name="camera1">
		    <update_rate>30.0</update_rate>
		    <camera name="camera_head">
		        <horizontal_fov>1.3962634</horizontal_fov>
		        <image>
		        	<width>800</width>
		        	<height>800</height>
		        	<format>R8G8B8</format>
		        </image>
		        <clip>
		        	<near>0.02</near>
		        	<far>300</far>
		        </clip>
		    </camera>
	    	<plugin name="camera_controller" filename="libgazebo_ros_camera.so">
		        <alwaysOn>true</alwaysOn>
		        <updateRate>0.0</updateRate>
		        <cameraName>assignment/camera1</cameraName>
		        <imageTopicName>image_raw</imageTopicName>
		        <cameraInfoTopicName>camera_info</cameraInfoTopicName>
		        <frameName>camera</frameName>
		        <hackBaseline>0.07</hackBaseline>
		        <distortionK1>0.0</distortionK1>
		        <distortionK2>0.0</distortionK2>
		        <distortionK3>0.0</distortionK3>
		        <distortionT1>0.0</distortionT1>
		        <distortionT2>0.0</distortionT2>
	    	</plugin>
	    </sensor>
	</gazebo>

####################### END #######################
</robot>
